<?xml version="1.0"?>
<sdf version="1.9">
  <model name="cessna_aircraft">
    <pose>0 0 0.246 0 0 0</pose>
    
    <link name="base_link">
      <pose>0 0 0 0 0 0</pose>
      <inertial>
        <pose>0 0 0 0 0 0</pose>
        <mass>2.0</mass>
        <inertia>
          <ixx>0.197563</ixx>
          <ixy>0</ixy>
          <ixz>0</ixz>
          <iyy>0.1458929</iyy>
          <iyz>0</iyz>
          <izz>0.1477</izz>
        </inertia>
      </inertial>

      <collision name="com_restrictor_board">
        <pose>0 0 0 0 0 0</pose>
        <geometry>
          <box>
            <size>1.0 1.0 0.01</size>
          </box>
        </geometry>
        <surface>
          <contact>
            <collide_bitmask>0x02</collide_bitmask>
          </contact>
          <friction>
            <ode>
              <mu>0.0</mu>
              <mu2>0.0</mu2>
            </ode>
          </friction>
        </surface>
      </collision>
      
      <collision name="fuselage_collision">
        <pose>-0.14 0 0 0 0 0</pose>
        <geometry>
          <box>
            <size>0.65 0.08 0.10</size>
          </box>
        </geometry>
        <surface>
          <contact>
            <collide_bitmask>0xFD</collide_bitmask>
            <ode>
              <max_vel>10</max_vel>
              <min_depth>0.01</min_depth>
            </ode>
          </contact>
        </surface>
      </collision>
      
      <collision name="wings_collision">
        <pose>-0.01 0 0.07 0 0 0</pose>
        <geometry>
          <box>
            <size>0.1 1.0 0.01</size>
          </box>
        </geometry>
        <surface>
          <contact>
            <collide_bitmask>0xFD</collide_bitmask>
            <ode>
              <max_vel>10</max_vel>
              <min_depth>0.01</min_depth>
            </ode>
          </contact>
        </surface>
      </collision>
      
      <visual name="base_link_visual">
        <pose>0.07 0 -0.08 0 0 0</pose>
        <geometry>
          <mesh>
            <scale>0.1 0.1 0.1</scale>
            <uri>model://cessna_aircraft/meshes/body.dae</uri>
          </mesh>
        </geometry>
        <material>
          <ambient>0.175 0.175 0.175 1.0</ambient>
          <diffuse>0.175 0.175 0.175 1.0</diffuse>
        </material>
      </visual>
      <gravity>1</gravity>
      <velocity_decay/>
      <self_collide>0</self_collide>
      
      <sensor name="imu_sensor" type="imu">
        <pose degrees="true">0 0 0 180 0 0</pose>
        <always_on>1</always_on>
        <update_rate>250.0</update_rate>
        <imu>
          <angular_velocity>
            <x>
              <noise type="gaussian">
                <mean>0</mean>
                <stddev>0.0003394</stddev>
                <dynamic_bias_stddev>3.8785e-05</dynamic_bias_stddev>
                <dynamic_bias_correlation_time>1000</dynamic_bias_correlation_time>
              </noise>
            </x>
            <y>
              <noise type="gaussian">
                <mean>0</mean>
                <stddev>0.0003394</stddev>
                <dynamic_bias_stddev>3.8785e-05</dynamic_bias_stddev>
                <dynamic_bias_correlation_time>1000</dynamic_bias_correlation_time>
              </noise>
            </y>
            <z>
              <noise type="gaussian">
                <mean>0</mean>
                <stddev>0.0003394</stddev>
                <dynamic_bias_stddev>3.8785e-05</dynamic_bias_stddev>
                <dynamic_bias_correlation_time>1000</dynamic_bias_correlation_time>
              </noise>
            </z>
          </angular_velocity>
          <linear_acceleration>
            <x>
              <noise type="gaussian">
                <mean>0</mean>
                <stddev>0.004</stddev>
                <dynamic_bias_stddev>0.006</dynamic_bias_stddev>
                <dynamic_bias_correlation_time>300</dynamic_bias_correlation_time>
              </noise>
            </x>
            <y>
              <noise type="gaussian">
                <mean>0</mean>
                <stddev>0.004</stddev>
                <dynamic_bias_stddev>0.006</dynamic_bias_stddev>
                <dynamic_bias_correlation_time>300</dynamic_bias_correlation_time>
              </noise>
            </y>
            <z>
              <noise type="gaussian">
                <mean>0</mean>
                <stddev>0.004</stddev>
                <dynamic_bias_stddev>0.006</dynamic_bias_stddev>
                <dynamic_bias_correlation_time>300</dynamic_bias_correlation_time>
              </noise>
            </z>
          </linear_acceleration>
        </imu>
      </sensor>

      <sensor name="navsat_sensor" type="navsat">
        <always_on>1</always_on>
        <update_rate>1</update_rate>
      </sensor>
      
      <sensor name="front_depth_camera" type="rgbd_camera">
        <pose degrees="true">0.35 0 0.05 0 -10 0</pose>
        <always_on>1</always_on>
        <update_rate>30.0</update_rate>
        <camera>
          <horizontal_fov>1.5</horizontal_fov>
          <image>
            <width>640</width>
            <height>480</height>
            <format>R8G8B8</format>
          </image>
          <clip>
            <near>0.2</near>
            <far>100.0</far>
          </clip>
        </camera>
      </sensor>
    </link>

    <link name="left_elevon">
      <inertial>
        <mass>0.01</mass>
        <inertia>
          <ixx>0.000001</ixx>
          <ixy>0.0</ixy>
          <iyy>0.000001</iyy>
          <ixz>0.0</ixz>
          <iyz>0.0</iyz>
          <izz>0.000001</izz>
        </inertia>
        <pose>0 0.3 0 0.00 0 0.0</pose>
      </inertial>
      <visual name="left_elevon_visual">
        <pose>0.07 0.0 -0.08 0.00 0 0.0</pose>
        <geometry>
          <mesh>
            <scale>0.1 0.1 0.1</scale>
            <uri>model://cessna_aircraft/meshes/left_aileron.dae</uri>
          </mesh>
        </geometry>
        <material>
          <ambient>0 0 1 1.0</ambient>
          <diffuse>0 0 1 1.0</diffuse>
        </material>
      </visual>
    </link>

    <link name="LeftWheel">
      <pose relative_to="LeftWheelJoint">0 0 0 0 0 0</pose>
      <inertial>
        <mass>0.05</mass>
        <inertia>
          <ixx>0.00003331</ixx>
          <ixy>0</ixy>
          <ixz>0</ixz>
          <iyy>0.0000204</iyy>
          <iyz>0</iyz>
          <izz>0.0000204</izz>
        </inertia>
      </inertial>
      <gravity>true</gravity>
      <velocity_decay/>
      <visual name="LeftWheelVisual">
        <pose>0 0 0 -1.57079632679 0 0</pose>
        <geometry>
          <cylinder>
            <length>0.01</length>
            <radius>0.03</radius>
          </cylinder>
        </geometry>
      </visual>
      <collision name="LeftWheelCollision">
        <pose>0 0 0 -1.57079632679 0 0</pose>
        <geometry>
          <cylinder>
            <length>0.01</length>
            <radius>0.03</radius>
          </cylinder>
        </geometry>
        <surface>
          <contact>
            <collide_bitmask>0xFD</collide_bitmask>
          </contact>
          <friction>
            <ode>
              <mu>1.0</mu>
              <mu2>0.5</mu2>
              <fdir1>0 0 1</fdir1>
            </ode>
          </friction>
        </surface>
      </collision>
    </link>

    <link name="RightWheel">
      <pose relative_to="RightWheelJoint">0 0 0 0 0 0</pose>
      <inertial>
        <mass>0.05</mass>
        <inertia>
          <ixx>0.00003331</ixx>
          <ixy>0</ixy>
          <ixz>0</ixz>
          <iyy>0.0000204</iyy>
          <iyz>0</iyz>
          <izz>0.0000204</izz>
        </inertia>
      </inertial>
      <gravity>true</gravity>
      <velocity_decay/>
      <visual name="RightWheelVisual">
        <pose>0 0 0 -1.57079632679 0 0</pose>
        <geometry>
          <cylinder>
            <length>0.01</length>
            <radius>0.03</radius>
          </cylinder>
        </geometry>
      </visual>
      <collision name="RightWheelCollision">
        <pose>0 0 0 -1.57079632679 0 0</pose>
        <geometry>
          <cylinder>
            <length>0.01</length>
            <radius>0.03</radius>
          </cylinder>
        </geometry>
        <surface>
          <contact>
            <collide_bitmask>0xFD</collide_bitmask>
          </contact>
          <friction>
            <ode>
              <mu>1.0</mu>
              <mu2>0.5</mu2>
              <fdir1>0 0 1</fdir1>
            </ode>
          </friction>
        </surface>
      </collision>
    </link>

    <link name="CenterWheel">
      <pose relative_to="CenterWheelJoint">0 0 0 0 0 0</pose>
      <inertial>
        <mass>0.05</mass>
        <inertia>
          <ixx>0.00003331</ixx>
          <ixy>0</ixy>
          <ixz>0</ixz>
          <iyy>0.0000204</iyy>
          <iyz>0</iyz>
          <izz>0.0000204</izz>
        </inertia>
      </inertial>
      <gravity>true</gravity>
      <velocity_decay/>
      <visual name="CenterWheelVisual">
        <pose>0 0 0 -1.57079632679 0 0</pose>
        <geometry>
          <cylinder>
            <length>0.01</length>
            <radius>0.025</radius>
          </cylinder>
        </geometry>
      </visual>
      <collision name="CenterWheelCollision">
        <pose>0 0 0 -1.57079632679 0 0</pose>
        <geometry>
          <cylinder>
            <length>0.01</length>
            <radius>0.025</radius>
          </cylinder>
        </geometry>
        <surface>
          <contact>
            <collide_bitmask>0xFD</collide_bitmask>
          </contact>
          <friction>
            <ode>
              <mu>1.0</mu>
              <mu2>1.0</mu2>
              <fdir1>0 0 1</fdir1>
            </ode>
          </friction>
        </surface>
      </collision>
    </link>

    <link name="right_elevon">
      <inertial>
        <mass>0.01</mass>
        <inertia>
          <ixx>0.000001</ixx>
          <ixy>0.0</ixy>
          <iyy>0.000001</iyy>
          <ixz>0.0</ixz>
          <iyz>0.0</iyz>
          <izz>0.000001</izz>
        </inertia>
        <pose>0 -0.3 0 0.00 0 0.0</pose>
      </inertial>
      <visual name="right_elevon_visual">
        <pose>0.07 0.0 -0.08 0.00 0 0.0</pose>
        <geometry>
          <mesh>
            <scale>0.1 0.1 0.1</scale>
            <uri>model://cessna_aircraft/meshes/right_aileron.dae</uri>
          </mesh>
        </geometry>
        <material>
          <ambient>0 0 1 1.0</ambient>
          <diffuse>0 0 1 1.0</diffuse>
        </material>
      </visual>
    </link>
    
    <link name="elevator">
      <inertial>
        <mass>0.01</mass>
        <inertia>
          <ixx>0.000001</ixx>
          <ixy>0.0</ixy>
          <iyy>0.000001</iyy>
          <ixz>0.0</ixz>
          <iyz>0.0</iyz>
          <izz>0.000001</izz>
        </inertia>
        <pose>-0.5 0 0 0.00 0 0.0</pose>
      </inertial>
      <visual name="elevator_visual">
        <pose>0.07 0.0 -0.08 0.00 0 0.0</pose>
        <geometry>
          <mesh>
            <scale>0.1 0.1 0.1</scale>
            <uri>model://cessna_aircraft/meshes/elevators.dae</uri>
          </mesh>
        </geometry>
        <material>
          <ambient>0 0 1 1.0</ambient>
          <diffuse>0 0 1 1.0</diffuse>
        </material>
      </visual>
    </link>

    <link name="rudder">
      <inertial>
        <mass>0.01</mass>
        <inertia>
          <ixx>0.000001</ixx>
          <ixy>0.0</ixy>
          <iyy>0.000001</iyy>
          <ixz>0.0</ixz>
          <iyz>0.0</iyz>
          <izz>0.000001</izz>
        </inertia>
        <pose>-0.5 0 0.05 0 0 0</pose>
      </inertial>
      <visual name="rudder_visual">
        <pose>0.07 0.0 -0.08 0.00 0 0.0</pose>
        <geometry>
          <mesh>
            <scale>0.1 0.1 0.1</scale>
            <uri>model://cessna_aircraft/meshes/rudder.dae</uri>
          </mesh>
        </geometry>
        <material>
          <ambient>0 0 1 1.0</ambient>
          <diffuse>0 0 1 1.0</diffuse>
        </material>
      </visual>
    </link>

    <joint name="servo_0" type="revolute">
      <parent>base_link</parent>
      <child>left_elevon</child>
      <pose>-0.07 0.4 0.08 0.00 0 0.0</pose>
      <axis>
        <xyz>0 1 0</xyz>
        <limit>
          <lower>-0.78</lower>
          <upper>0.78</upper>
        </limit>
        <dynamics>
          <damping>0.0100</damping>
        </dynamics>
      </axis>
      <physics>
        <ode>
          <implicit_spring_damper>1</implicit_spring_damper>
        </ode>
      </physics>
    </joint>

    <joint name="servo_1" type="revolute">
      <parent>base_link</parent>
      <child>right_elevon</child>
      <pose>-0.07 -0.4 0.08 0.00 0 0.0</pose>
      <axis>
        <xyz>0 1 0</xyz>
        <limit>
          <lower>-0.78</lower>
          <upper>0.78</upper>
        </limit>
        <dynamics>
          <damping>0.0100</damping>
        </dynamics>
      </axis>
      <physics>
        <ode>
          <implicit_spring_damper>1</implicit_spring_damper>
        </ode>
      </physics>
    </joint>

    <joint name="servo_2" type="revolute">
      <parent>base_link</parent>
      <child>elevator</child>
      <pose>-0.5 0 0 0 0 0</pose>
      <axis>
        <xyz>0 1 0</xyz>
        <limit>
          <lower>-0.78</lower>
          <upper>0.78</upper>
        </limit>
        <dynamics>
          <damping>0.0100</damping>
        </dynamics>
      </axis>
      <physics>
        <ode>
          <implicit_spring_damper>1</implicit_spring_damper>
        </ode>
      </physics>
    </joint>

    <joint name="rudder_joint" type="revolute">
      <parent>base_link</parent>
      <child>rudder</child>
      <pose>-0.5 0 0.05 0.00 0 0.0</pose>
      <axis>
        <xyz>0 0 1</xyz>
        <limit>
          <lower>-0.78</lower>
          <upper>0.78</upper>
        </limit>
        <dynamics>
          <damping>0.0100</damping>
        </dynamics>
      </axis>
      <physics>
        <ode>
          <implicit_spring_damper>1</implicit_spring_damper>
        </ode>
      </physics>
    </joint>

    <joint name="LeftWheelJoint" type="revolute">
      <parent>base_link</parent>
      <child>LeftWheel</child>
      <pose relative_to="base_link">-0.035 0.13 -0.12 0 0 0</pose>
      <axis>
        <xyz>0 1 0</xyz>
        <limit>
          <lower>-1.79769e+308</lower>
          <upper>1.79769e+308</upper>
        </limit>
        <dynamics>
          <friction>0.02</friction>
          <spring_reference>0</spring_reference>
          <spring_stiffness>0</spring_stiffness>
        </dynamics>
      </axis>
    </joint>

    <joint name="RightWheelJoint" type="revolute">
      <parent>base_link</parent>
      <child>RightWheel</child>
      <pose relative_to="base_link">-0.035 -0.13 -0.12 0 0 0</pose>
      <axis>
        <xyz>0 1 0</xyz>
        <limit>
          <lower>-1.79769e+308</lower>
          <upper>1.79769e+308</upper>
        </limit>
        <dynamics>
          <friction>0.02</friction>
          <spring_reference>0</spring_reference>
          <spring_stiffness>0</spring_stiffness>
        </dynamics>
      </axis>
    </joint>

    <joint name="CenterWheelJoint" type="revolute">
      <parent>base_link</parent>
      <child>CenterWheel</child>
      <pose relative_to="base_link">0.135 0 -0.12 0 0 0</pose>
      <axis>
        <xyz>0 1 0</xyz>
        <limit>
          <lower>-1.79769e+308</lower>
          <upper>1.79769e+308</upper>
        </limit>
        <dynamics>
          <friction>0.02</friction>
          <spring_reference>0</spring_reference>
          <spring_stiffness>0</spring_stiffness>
        </dynamics>
      </axis>
    </joint>

    <link name="motor_link">
      <pose>0.22 0 0.0 0 1.57079632679 0</pose>
      <inertial>
        <pose>0 0 0 0 0 0</pose>
        <mass>0.0000005</mass>
        <inertia>
          <ixx>9.75e-07</ixx>
          <ixy>0</ixy>
          <ixz>0</ixz>
          <iyy>0.000166704</iyy>
          <iyz>0</iyz>
          <izz>0.000167604</izz>
        </inertia>
      </inertial>
      <collision name="motor_link_collision">
        <pose>0 0 0 0 -1.57079632679 0</pose>
        <geometry>
          <box>
            <size>0.005 0.22 0.02</size>
          </box>
        </geometry>
        <surface>
          <contact>
            <collide_bitmask>0xFD</collide_bitmask>
            <ode/>
          </contact>
          <friction>
            <ode/>
          </friction>
        </surface>
      </collision>
      <visual name="motor_link_visual">
        <pose>0 0 0 0 0 -1.57079632679</pose>
        <geometry>
          <mesh>
            <scale>1 1 1</scale>
            <uri>model://cessna_aircraft/meshes/iris_prop_ccw.dae</uri>
          </mesh>
        </geometry>
        <material>
          <ambient>0 0 1 1.0</ambient>
          <diffuse>0 0 1 1.0</diffuse>
        </material>
      </visual>
      <gravity>1</gravity>
      <velocity_decay/>
      <self_collide>0</self_collide>
    </link>

    <joint name="motor_joint" type="revolute">
      <pose degrees="true">0 0 0 0 180 0</pose>
      <child>motor_link</child>
      <parent>base_link</parent>
      <axis>
        <xyz>0 0 1</xyz>
        <limit>
          <lower>-1e+16</lower>
          <upper>1e+16</upper>
        </limit>
        <dynamics>
          <spring_reference>0</spring_reference>
          <spring_stiffness>0</spring_stiffness>
        </dynamics>
      </axis>
    </joint>
    
    <link name="left_flap">
      <inertial>
        <mass>0.00000001</mass>
        <inertia>
          <ixx>0.000001</ixx>
          <ixy>0.0</ixy>
          <iyy>0.000001</iyy>
          <ixz>0.0</ixz>
          <iyz>0.0</iyz>
          <izz>0.000001</izz>
        </inertia>
        <pose>0 0.15 0 0.00 0 0.0</pose>
      </inertial>
      <visual name="left_flap_visual">
        <pose>0.07 0.0 -0.08 0.00 0 0.0</pose>
        <geometry>
          <mesh>
            <scale>0.1 0.1 0.1</scale>
            <uri>model://cessna_aircraft/meshes/left_flap.dae</uri>
          </mesh>
        </geometry>
        <material>
          <ambient>0 0 1 1.0</ambient>
          <diffuse>0 0 1 1.0</diffuse>
        </material>
      </visual>
    </link>

    <link name="right_flap">
      <inertial>
        <mass>0.00000001</mass>
        <inertia>
          <ixx>0.000001</ixx>
          <ixy>0.0</ixy>
          <iyy>0.000001</iyy>
          <ixz>0.0</ixz>
          <iyz>0.0</iyz>
          <izz>0.000001</izz>
        </inertia>
        <pose>0 -0.15 0 0.00 0 0.0</pose>
      </inertial>
      <visual name="right_flap_visual">
        <pose>0.07 0.0 -0.08 0.00 0 0.0</pose>
        <geometry>
          <mesh>
            <scale>0.1 0.1 0.1</scale>
            <uri>model://cessna_aircraft/meshes/right_flap.dae</uri>
          </mesh>
        </geometry>
        <material>
          <ambient>0 0 1 1.0</ambient>
          <diffuse>0 0 1 1.0</diffuse>
        </material>
      </visual>
    </link>

    <joint name="left_flap_joint" type="revolute">
      <parent>base_link</parent>
      <child>left_flap</child>
      <pose>-0.07 0.2 0.08 0.00 0 0.0</pose>
      <axis>
        <xyz>0 1 0</xyz>
        <limit>
          <lower>-0.78</lower>
          <upper>0.78</upper>
        </limit>
        <dynamics>
          <damping>1.000</damping>
        </dynamics>
      </axis>
      <physics>
        <ode>
          <implicit_spring_damper>1</implicit_spring_damper>
        </ode>
      </physics>
    </joint>

    <joint name="right_flap_joint" type="revolute">
      <parent>base_link</parent>
      <child>right_flap</child>
      <pose>-0.07 -0.2 0.08 0.00 0 0.0</pose>
      <axis>
        <xyz>0 1 0</xyz>
        <limit>
          <lower>-0.78</lower>
          <upper>0.78</upper>
        </limit>
        <dynamics>
          <damping>1.000</damping>
        </dynamics>
      </axis>
      <physics>
        <ode>
          <implicit_spring_damper>1</implicit_spring_damper>
        </ode>
      </physics>
    </joint>

    <plugin filename="gz-sim-joint-state-publisher-system" name="gz::sim::systems::JointStatePublisher"></plugin>

    <plugin filename="gz-sim-joint-position-controller-system" name="gz::sim::systems::JointPositionController">
      <joint_name>servo_0</joint_name>
      <initial_position>0.0</initial_position>
      <topic>/left_aileron_joint/cmd_pos</topic>
      <p_gain>10</p_gain>
      <i_gain>0.0</i_gain>
      <d_gain>0.0</d_gain>
      <i_max>1</i_max>
      <i_min>-1</i_min>
      <cmd_max>5</cmd_max>
      <cmd_min>-5</cmd_min>
    </plugin>

    <plugin filename="gz-sim-joint-position-controller-system" name="gz::sim::systems::JointPositionController">
      <joint_name>servo_1</joint_name>
      <initial_position>0.0</initial_position>
      <topic>/right_aileron_joint/cmd_pos</topic>
      <p_gain>10</p_gain>
      <i_gain>0.0</i_gain>
      <d_gain>0.0</d_gain>
      <i_max>1</i_max>
      <i_min>-1</i_min>
      <cmd_max>5</cmd_max>
      <cmd_min>-5</cmd_min>
    </plugin>

    <plugin filename="gz-sim-joint-position-controller-system" name="gz::sim::systems::JointPositionController">
      <joint_name>rudder_joint</joint_name>
      <initial_position>0.0</initial_position>
      <topic>/rudder/cmd_pos</topic>
      <p_gain>10</p_gain>
      <i_gain>0.0</i_gain>
      <d_gain>0.0</d_gain>
      <i_max>1</i_max>
      <i_min>-1</i_min>
      <cmd_max>5</cmd_max>
      <cmd_min>-5</cmd_min>
    </plugin>
    
    <plugin filename="gz-sim-joint-position-controller-system" name="gz::sim::systems::JointPositionController">
      <joint_name>servo_2</joint_name>
      <initial_position>0.0</initial_position>
      <topic>/elevator/cmd_pos</topic>
      <p_gain>10</p_gain>
      <i_gain>0.0</i_gain>
      <d_gain>0.0</d_gain>
      <i_max>1</i_max>
      <i_min>-1</i_min>
      <cmd_max>5</cmd_max>
      <cmd_min>-5</cmd_min>
    </plugin>

    <plugin filename="gz-sim-lift-drag-system" name="gz::sim::systems::LiftDrag">
      <a0>0.3</a0>
      <alpha_stall>1.4</alpha_stall>
      <cla>4.25</cla>
      <cda>0.10</cda>
      <cma>0.00</cma>
      <cla_stall>-0.025</cla_stall>
      <cda_stall>0.0</cda_stall>
      <cma_stall>0.0</cma_stall>
      <area>0.02</area>
      <air_density>1.2041</air_density>
      <cp>0.084 0 0</cp>
      <forward>0 -1 0</forward>
      <upward>0 0 1</upward>
      <link_name>motor_link</link_name>
    </plugin>

    <plugin filename="gz-sim-lift-drag-system" name="gz::sim::systems::LiftDrag">
      <a0>0.3</a0>
      <alpha_stall>1.4</alpha_stall>
      <cla>4.25</cla>
      <cda>0.10</cda>
      <cma>0.00</cma>
      <cla_stall>-0.025</cla_stall>
      <cda_stall>0.0</cda_stall>
      <cma_stall>0.0</cma_stall>
      <area>0.02</area>
      <air_density>1.2041</air_density>
      <cp>-0.084 0 0</cp>
      <forward>0 1 0</forward>
      <upward>0 0 1</upward>
      <link_name>motor_link</link_name>
    </plugin>

    <plugin filename="gz-sim-lift-drag-system" name="gz::sim::systems::LiftDrag">
      <a0>0.05984281113</a0>
      <cla>4.752798721</cla>
      <cda>1.5</cda>
      <cma>0.0</cma>
      <alpha_stall>0.3391428111</alpha_stall>
      <cla_stall>-3.85</cla_stall>
      <cda_stall>-0.9233984055</cda_stall>
      <cma_stall>0</cma_stall>
      <cp>-0.05 0.45 0.05</cp>
      <area>0.6</area>
      <air_density>1.2041</air_density>
      <forward>1 0 0</forward>
      <upward>0 0 1</upward>
      <link_name>base_link</link_name>
      <control_joint_name>servo_0</control_joint_name>
      <control_joint_rad_to_cl>-0.75</control_joint_rad_to_cl>
    </plugin>

    <plugin filename="gz-sim-lift-drag-system" name="gz::sim::systems::LiftDrag">
      <a0>0.05984281113</a0>
      <cla>4.752798721</cla>
      <cda>1.5</cda>
      <cma>0.0</cma>
      <alpha_stall>0.3391428111</alpha_stall>
      <cla_stall>-3.85</cla_stall>
      <cda_stall>-0.9233984055</cda_stall>
      <cma_stall>0</cma_stall>
      <cp>-0.05 -0.45 0.05</cp>
      <area>0.6</area>
      <air_density>1.2041</air_density>
      <forward>1 0 0</forward>
      <upward>0 0 1</upward>
      <link_name>base_link</link_name>
      <control_joint_name>servo_1</control_joint_name>
      <control_joint_rad_to_cl>-0.75</control_joint_rad_to_cl>
    </plugin>

    <plugin filename="gz-sim-lift-drag-system" name="gz::sim::systems::LiftDrag">
      <a0>0.0</a0>
      <cla>4.752798721</cla>
      <cda>0.6417112299</cda>
      <cma>0.0</cma>
      <alpha_stall>0.3391428111</alpha_stall>
      <cla_stall>-3.85</cla_stall>
      <cda_stall>-0.9233984055</cda_stall>
      <cma_stall>0</cma_stall>
      <cp>-0.5 0 0.05</cp>
      <area>0.1</area>
      <air_density>1.2041</air_density>
      <forward>1 0 0</forward>
      <upward>0 1 0</upward>
      <link_name>base_link</link_name>
      <control_joint_name>rudder_joint</control_joint_name>
      <control_joint_rad_to_cl>0.8</control_joint_rad_to_cl>
    </plugin>
    
    <plugin filename="gz-sim-lift-drag-system" name="gz::sim::systems::LiftDrag">
      <a0>-0.2</a0>
      <cla>4.752798721</cla>
      <cda>0.6417112299</cda>
      <cma>0.0</cma>
      <alpha_stall>0.3391428111</alpha_stall>
      <cla_stall>-3.85</cla_stall>
      <cda_stall>-0.9233984055</cda_stall>
      <cma_stall>0</cma_stall>
      <cp>-0.5 0 0</cp>
      <area>0.01</area>
      <air_density>1.2041</air_density>
      <forward>1 0 0</forward>
      <upward>0 0 1</upward>
      <link_name>base_link</link_name>
      <control_joint_name>servo_2</control_joint_name>
      <control_joint_rad_to_cl>-4.0</control_joint_rad_to_cl>
    </plugin>
    
    <plugin filename="gz-sim-lift-drag-system" name="gz::sim::systems::LiftDrag">
      <a0>0.05984281113</a0>
      <cla>4.752798721</cla>
      <cda>0.6417112299</cda>
      <cma>0.0</cma>
      <alpha_stall>0.3391428111</alpha_stall>
      <cla_stall>-3.85</cla_stall>
      <cda_stall>-0.9233984055</cda_stall>
      <cma_stall>0</cma_stall>
      <cp>-0.05 0.15 0.05</cp>
      <area>0.6</area>
      <air_density>1.2041</air_density>
      <forward>1 0 0</forward>
      <upward>0 0 1</upward>
      <link_name>base_link</link_name>
      <control_joint_name>left_flap_joint</control_joint_name>
      <control_joint_rad_to_cl>-0.1</control_joint_rad_to_cl>
    </plugin>

    <plugin filename="gz-sim-lift-drag-system" name="gz::sim::systems::LiftDrag">
      <a0>0.05984281113</a0>
      <cla>4.752798721</cla>
      <cda>0.6417112299</cda>
      <cma>0.0</cma>
      <alpha_stall>0.3391428111</alpha_stall>
      <cla_stall>-3.85</cla_stall>
      <cda_stall>-0.9233984055</cda_stall>
      <cma_stall>0</cma_stall>
      <cp>-0.05 -0.15 0.05</cp>
      <area>0.6</area>
      <air_density>1.2041</air_density>
      <forward>1 0 0</forward>
      <upward>0 0 1</upward>
      <link_name>base_link</link_name>
      <control_joint_name>right_flap_joint</control_joint_name>
      <control_joint_rad_to_cl>-0.1</control_joint_rad_to_cl>
    </plugin>

    <plugin name="ArduPilotPlugin" filename="ArduPilotPlugin">
      <fdm_addr>127.0.0.1</fdm_addr>
      <fdm_port_in>9002</fdm_port_in>
      <connectionTimeoutMaxCount>5</connectionTimeoutMaxCount>
      <lock_step>1</lock_step>
      <have_32_channels>0</have_32_channels>

      <modelXYZToAirplaneXForwardZDown>0 0 0 3.141593 0 0</modelXYZToAirplaneXForwardZDown>
      <gazeboXYZToNED>0 0 0 3.141593 0 1.57079632</gazeboXYZToNED>

      <imuName>base_link::imu_sensor</imuName>

      <control channel="0">
        <jointName>servo_0</jointName>
        <multiplier>-1.0471976</multiplier>
        <offset>-0.5</offset>
        <servo_min>1000</servo_min>
        <servo_max>2000</servo_max>
        <type>COMMAND</type>
        <cmd_topic>/left_aileron_joint/cmd_pos</cmd_topic>
      </control>

      <control channel="0">
        <jointName>servo_1</jointName>
        <multiplier>1.0471976</multiplier>
        <offset>-0.5</offset>
        <servo_min>1000</servo_min>
        <servo_max>2000</servo_max>
        <type>COMMAND</type>
        <cmd_topic>/right_aileron_joint/cmd_pos</cmd_topic>
      </control>

      <control channel="1">
        <jointName>servo_2</jointName>
        <multiplier>1.0471976</multiplier>
        <offset>-0.5</offset>
        <servo_min>1000</servo_min>
        <servo_max>2000</servo_max>
        <type>COMMAND</type>
        <cmd_topic>/elevator/cmd_pos</cmd_topic>
      </control>

      <control channel="2"> 
        <jointName>motor_joint</jointName>
        <multiplier>1000</multiplier>
        <offset>0</offset>
        <servo_min>1000</servo_min>
        <servo_max>2000</servo_max>
        <type>VELOCITY</type>
        <p_gain>0.20</p_gain>
        <i_gain>0</i_gain>
        <d_gain>0</d_gain>
        <i_max>1</i_max>
        <i_min>-1</i_min>
        <cmd_max>5.0</cmd_max>
        <cmd_min>-5.0</cmd_min>
      </control>

      <control channel="3">
        <jointName>rudder_joint</jointName>
        <multiplier>1.0471976</multiplier>
        <offset>-0.5</offset>
        <servo_min>1000</servo_min>
        <servo_max>2000</servo_max>
        <type>COMMAND</type>
        <cmd_topic>/rudder/cmd_pos</cmd_topic>
      </control>
    </plugin>    


  </model>
</sdf>
